[2025-02-14 02:05:36,937] {taskinstance.py:896} INFO - Dependencies all met for <TaskInstance: Project.task_one 2025-02-14T02:05:28.760611+00:00 [queued]>
[2025-02-14 02:05:36,954] {taskinstance.py:896} INFO - Dependencies all met for <TaskInstance: Project.task_one 2025-02-14T02:05:28.760611+00:00 [queued]>
[2025-02-14 02:05:36,955] {taskinstance.py:1087} INFO - 
--------------------------------------------------------------------------------
[2025-02-14 02:05:36,955] {taskinstance.py:1088} INFO - Starting attempt 1 of 1
[2025-02-14 02:05:36,955] {taskinstance.py:1089} INFO - 
--------------------------------------------------------------------------------
[2025-02-14 02:05:36,965] {taskinstance.py:1107} INFO - Executing <Task(PythonOperator): task_one> on 2025-02-14T02:05:28.760611+00:00
[2025-02-14 02:05:36,968] {standard_task_runner.py:52} INFO - Started process 3380 to run task
[2025-02-14 02:05:36,973] {standard_task_runner.py:76} INFO - Running: ['***', 'tasks', 'run', 'Project', 'task_one', '2025-02-14T02:05:28.760611+00:00', '--job-id', '103', '--pool', 'default_pool', '--raw', '--subdir', 'DAGS_FOLDER/assignment.py', '--cfg-path', '/tmp/tmpdnga8aqk', '--error-file', '/tmp/tmp2fk4n7z6']
[2025-02-14 02:05:36,974] {standard_task_runner.py:77} INFO - Job 103: Subtask task_one
[2025-02-14 02:05:37,028] {logging_mixin.py:104} INFO - Running <TaskInstance: Project.task_one 2025-02-14T02:05:28.760611+00:00 [running]> on host 81ce9e7c2327
[2025-02-14 02:05:37,085] {taskinstance.py:1302} INFO - Exporting the following env vars:
AIRFLOW_CTX_DAG_OWNER=***
AIRFLOW_CTX_DAG_ID=Project
AIRFLOW_CTX_TASK_ID=task_one
AIRFLOW_CTX_EXECUTION_DATE=2025-02-14T02:05:28.760611+00:00
AIRFLOW_CTX_DAG_RUN_ID=manual__2025-02-14T02:05:28.760611+00:00
[2025-02-14 02:05:37,088] {taskinstance.py:1501} ERROR - Task failed with exception
Traceback (most recent call last):
  File "/home/airflow/.local/lib/python3.6/site-packages/airflow/models/taskinstance.py", line 1157, in _run_raw_task
    self._prepare_and_execute_task_with_callbacks(context, task)
  File "/home/airflow/.local/lib/python3.6/site-packages/airflow/models/taskinstance.py", line 1331, in _prepare_and_execute_task_with_callbacks
    result = self._execute_task(context, task_copy)
  File "/home/airflow/.local/lib/python3.6/site-packages/airflow/models/taskinstance.py", line 1361, in _execute_task
    result = task_copy.execute(context=context)
  File "/home/airflow/.local/lib/python3.6/site-packages/airflow/operators/python.py", line 150, in execute
    return_value = self.execute_callable()
  File "/home/airflow/.local/lib/python3.6/site-packages/airflow/operators/python.py", line 161, in execute_callable
    return self.python_callable(*self.op_args, **self.op_kwargs)
  File "/opt/airflow/dags/assignment.py", line 30, in catalog
    with open("00_urls.txt", "r", encoding="utf-8") as f:
FileNotFoundError: [Errno 2] No such file or directory: '00_urls.txt'
[2025-02-14 02:05:37,093] {taskinstance.py:1551} INFO - Marking task as FAILED. dag_id=Project, task_id=task_one, execution_date=20250214T020528, start_date=20250214T020536, end_date=20250214T020537
[2025-02-14 02:05:37,155] {local_task_job.py:151} INFO - Task exited with return code 1
