[2025-02-14 02:12:10,845] {taskinstance.py:896} INFO - Dependencies all met for <TaskInstance: Project.task_one 2025-02-14T02:12:03.529015+00:00 [queued]>
[2025-02-14 02:12:10,861] {taskinstance.py:896} INFO - Dependencies all met for <TaskInstance: Project.task_one 2025-02-14T02:12:03.529015+00:00 [queued]>
[2025-02-14 02:12:10,861] {taskinstance.py:1087} INFO - 
--------------------------------------------------------------------------------
[2025-02-14 02:12:10,862] {taskinstance.py:1088} INFO - Starting attempt 1 of 1
[2025-02-14 02:12:10,862] {taskinstance.py:1089} INFO - 
--------------------------------------------------------------------------------
[2025-02-14 02:12:10,870] {taskinstance.py:1107} INFO - Executing <Task(PythonOperator): task_one> on 2025-02-14T02:12:03.529015+00:00
[2025-02-14 02:12:10,877] {standard_task_runner.py:76} INFO - Running: ['***', 'tasks', 'run', 'Project', 'task_one', '2025-02-14T02:12:03.529015+00:00', '--job-id', '107', '--pool', 'default_pool', '--raw', '--subdir', 'DAGS_FOLDER/assignment.py', '--cfg-path', '/tmp/tmplfdiawl9', '--error-file', '/tmp/tmp6b_2tsf6']
[2025-02-14 02:12:10,873] {standard_task_runner.py:52} INFO - Started process 4050 to run task
[2025-02-14 02:12:10,878] {standard_task_runner.py:77} INFO - Job 107: Subtask task_one
[2025-02-14 02:12:10,925] {logging_mixin.py:104} INFO - Running <TaskInstance: Project.task_one 2025-02-14T02:12:03.529015+00:00 [running]> on host 81ce9e7c2327
[2025-02-14 02:12:10,983] {taskinstance.py:1302} INFO - Exporting the following env vars:
AIRFLOW_CTX_DAG_OWNER=***
AIRFLOW_CTX_DAG_ID=Project
AIRFLOW_CTX_TASK_ID=task_one
AIRFLOW_CTX_EXECUTION_DATE=2025-02-14T02:12:03.529015+00:00
AIRFLOW_CTX_DAG_RUN_ID=manual__2025-02-14T02:12:03.529015+00:00
[2025-02-14 02:12:10,984] {taskinstance.py:1501} ERROR - Task failed with exception
Traceback (most recent call last):
  File "/home/airflow/.local/lib/python3.6/site-packages/airflow/models/taskinstance.py", line 1157, in _run_raw_task
    self._prepare_and_execute_task_with_callbacks(context, task)
  File "/home/airflow/.local/lib/python3.6/site-packages/airflow/models/taskinstance.py", line 1331, in _prepare_and_execute_task_with_callbacks
    result = self._execute_task(context, task_copy)
  File "/home/airflow/.local/lib/python3.6/site-packages/airflow/models/taskinstance.py", line 1361, in _execute_task
    result = task_copy.execute(context=context)
  File "/home/airflow/.local/lib/python3.6/site-packages/airflow/operators/python.py", line 150, in execute
    return_value = self.execute_callable()
  File "/home/airflow/.local/lib/python3.6/site-packages/airflow/operators/python.py", line 161, in execute_callable
    return self.python_callable(*self.op_args, **self.op_kwargs)
  File "/opt/airflow/dags/assignment.py", line 30, in catalog
    with open("00_urls.txt", "r", encoding="utf-8") as f:
FileNotFoundError: [Errno 2] No such file or directory: '00_urls.txt'
[2025-02-14 02:12:10,987] {taskinstance.py:1551} INFO - Marking task as FAILED. dag_id=Project, task_id=task_one, execution_date=20250214T021203, start_date=20250214T021210, end_date=20250214T021210
[2025-02-14 02:12:11,020] {local_task_job.py:151} INFO - Task exited with return code 1
