[2025-02-14 02:29:47,144] {taskinstance.py:896} INFO - Dependencies all met for <TaskInstance: Project.task_one 2025-02-14T02:29:39.228867+00:00 [queued]>
[2025-02-14 02:29:47,154] {taskinstance.py:896} INFO - Dependencies all met for <TaskInstance: Project.task_one 2025-02-14T02:29:39.228867+00:00 [queued]>
[2025-02-14 02:29:47,155] {taskinstance.py:1087} INFO - 
--------------------------------------------------------------------------------
[2025-02-14 02:29:47,155] {taskinstance.py:1088} INFO - Starting attempt 1 of 1
[2025-02-14 02:29:47,155] {taskinstance.py:1089} INFO - 
--------------------------------------------------------------------------------
[2025-02-14 02:29:47,166] {taskinstance.py:1107} INFO - Executing <Task(PythonOperator): task_one> on 2025-02-14T02:29:39.228867+00:00
[2025-02-14 02:29:47,175] {standard_task_runner.py:76} INFO - Running: ['***', 'tasks', 'run', 'Project', 'task_one', '2025-02-14T02:29:39.228867+00:00', '--job-id', '117', '--pool', 'default_pool', '--raw', '--subdir', 'DAGS_FOLDER/assignment.py', '--cfg-path', '/tmp/tmp7ulzc6qg', '--error-file', '/tmp/tmpqo2i6dy2']
[2025-02-14 02:29:47,170] {standard_task_runner.py:52} INFO - Started process 1171 to run task
[2025-02-14 02:29:47,176] {standard_task_runner.py:77} INFO - Job 117: Subtask task_one
[2025-02-14 02:29:47,214] {logging_mixin.py:104} INFO - Running <TaskInstance: Project.task_one 2025-02-14T02:29:39.228867+00:00 [running]> on host ad36e95eb2b4
[2025-02-14 02:29:47,258] {taskinstance.py:1302} INFO - Exporting the following env vars:
AIRFLOW_CTX_DAG_OWNER=***
AIRFLOW_CTX_DAG_ID=Project
AIRFLOW_CTX_TASK_ID=task_one
AIRFLOW_CTX_EXECUTION_DATE=2025-02-14T02:29:39.228867+00:00
AIRFLOW_CTX_DAG_RUN_ID=manual__2025-02-14T02:29:39.228867+00:00
[2025-02-14 02:29:47,259] {taskinstance.py:1501} ERROR - Task failed with exception
Traceback (most recent call last):
  File "/home/airflow/.local/lib/python3.6/site-packages/airflow/models/taskinstance.py", line 1157, in _run_raw_task
    self._prepare_and_execute_task_with_callbacks(context, task)
  File "/home/airflow/.local/lib/python3.6/site-packages/airflow/models/taskinstance.py", line 1331, in _prepare_and_execute_task_with_callbacks
    result = self._execute_task(context, task_copy)
  File "/home/airflow/.local/lib/python3.6/site-packages/airflow/models/taskinstance.py", line 1361, in _execute_task
    result = task_copy.execute(context=context)
  File "/home/airflow/.local/lib/python3.6/site-packages/airflow/operators/python.py", line 150, in execute
    return_value = self.execute_callable()
  File "/home/airflow/.local/lib/python3.6/site-packages/airflow/operators/python.py", line 161, in execute_callable
    return self.python_callable(*self.op_args, **self.op_kwargs)
  File "/opt/airflow/dags/assignment.py", line 30, in catalog
    with open("urls.txt", "r", encoding="utf-8") as f:
FileNotFoundError: [Errno 2] No such file or directory: 'urls.txt'
[2025-02-14 02:29:47,261] {taskinstance.py:1551} INFO - Marking task as FAILED. dag_id=Project, task_id=task_one, execution_date=20250214T022939, start_date=20250214T022947, end_date=20250214T022947
[2025-02-14 02:29:47,317] {local_task_job.py:151} INFO - Task exited with return code 1
